For ``unittest``-based tests, exceptions during class cleanup (as raised by functions registered with :meth:`TestCase.addClassCleanup <unittest.TestCase.addClassCleanup>`) are now reported instead of silently failing.
