Self-testing: corrected expected message for ``test_doctest_unexpected_exception`` in Python ``3.14``.
